<?xml version="1.0"?>
<!-- This URDF was automatically created by SolidWorks to URDF Exporter! Originally created by Stephen Brawner (brawner@gmail.com) 
     Commit Version: 1.6.0-1-g15f4949  Build Version: 1.6.7594.29634
     For more information, please see http://wiki.ros.org/sw_urdf_exporter -->


<robot name="water_base" xmlns:xacro="http://ros.org/wiki/xacro">
  <xacro:property name="M_PI" value="3.1415926535897931" /> 
  <link
    name="base_link">
    <!-- r=0.26 -->>
    <inertial>
      <origin
        xyz="0.000104664511012093 0.0049105114230535 0.145650059711867"
        rpy="0 0 0" />
      <mass
        value="3.71154442446242" />
      <inertia
        ixx="0.0465430882693072"
        ixy="0"
        ixz="0"
        iyy="0.0625130465095892"
        iyz="0"
        izz="0.0934102121820444" />
    </inertial>
    <visual>
      <origin      
        xyz="0 0 0"
        rpy="0 0 -${M_PI/2}" />
      <geometry>
        <mesh
          filename="package://water_description/meshes/base_link.STL" />
      </geometry>
      <material
        name="">
        <color
          rgba="0.752941176470588 0.752941176470588 0.752941176470588 1" />
      </material>
    </visual>
    <collision>
      <origin
        xyz="0 0 0"
        rpy="0 0 0" />
      <geometry>
        <mesh
          filename="package://water_description/meshes/base_link.STL" />
      </geometry>
    </collision>
  </link>

 <joint name="base_link2_joint" type="fixed">
    <parent link="base_link"/>
    <child link="base_link2"/>
    <origin xyz="0.0 0.0 0.0" rpy="0 0 -${M_PI/2}"/>
    <axis xyz="0 0 1"/>
  </joint>

  <link name="base_link2">
    <visual>
      <geometry>
        <cylinder length="0.0206" radius="0.00035"/>
      </geometry>
      <origin xyz="0 0 0" rpy="0 0 0"/>
    </visual>
    <collision>
      <geometry>
        <cylinder length="0.0206" radius="0.035"/>
      </geometry>
      <origin rpy="0 0 0" xyz="0 0 0"/>
    </collision>
    <inertial>
      <mass value="0.01" />
      <origin xyz="0 0 0" />
      <inertia ixx="0.001" ixy="0.0" ixz="0.0"
                iyy="0.001" iyz="0.0"
                izz="0.001" />
    </inertial>
  </link>




 <joint name="wheel_left_joint" type="continuous">
    <parent link="base_link2"/>
    <child link="wheel_left_link"/>
    <origin xyz="${0.40/2} 0.0 -0.04" rpy="${-M_PI/2} 0 ${M_PI/2}"/>
    <axis xyz="0 0 1"/>
  </joint>

  <link name="wheel_left_link">
    <visual>
      <material
        name="">
        <color
          rgba="1.0 1.0 1.0 1" />
      </material>    
      <geometry>
        <cylinder length="0.0206" radius="0.028"/>
      </geometry>
      <origin xyz="0 0 0" rpy="0 0 0"/>
    </visual>
    <collision>
      <geometry>
        <cylinder length="0.0206" radius="0.028"/>
      </geometry>
      <origin rpy="0 0 0" xyz="0 0 0"/>
    </collision>
    <inertial>
      <mass value="0.01" />
      <origin xyz="0 0 0" />
      <inertia ixx="0.001" ixy="0.0" ixz="0.0"
                iyy="0.001" iyz="0.0"
                izz="0.001" />
    </inertial>
  </link>

  <joint name="wheel_right_joint" type="continuous">
    <parent link="base_link2"/>
    <child link="wheel_right_link"/>
    <origin xyz="-${0.40/2} 0.0 -0.04" rpy="${-M_PI/2} 0 ${M_PI/2}"/>
    <axis xyz="0 0 1"/>
  </joint>
  <link name="wheel_right_link">
    <visual>
      <material
        name="">
        <color
          rgba="1.0 1.0 1.0 1" />
      </material>    
      <geometry>
        <cylinder length="0.0206" radius="0.028"/>
      </geometry>
      <origin xyz="0 0 0" rpy="0 0 0"/>
    </visual>
    <collision>
      <geometry>
        <cylinder length="0.0206" radius="0.028"/>
      </geometry>
      <origin rpy="0 0 0" xyz="0 0 0"/>
    </collision>
    <inertial>
      <mass value="0.01" />
      <origin xyz="0 0 0" />
      <inertia ixx="0.001" ixy="0.0" ixz="0.0"
                iyy="0.001" iyz="0.0"
                izz="0.001" />
    </inertial>
  </link>

  <joint name="caster_front_joint" type="fixed">
    <parent link="base_link2"/>
    <child link="caster_front_link"/>
    <origin xyz="0 0.15 -0.05" rpy="${-M_PI/2} 0 ${M_PI/2}"/>
  </joint>
  <link name="caster_front_link">
    <collision>
      <geometry>
        <cylinder length="0.0176" radius="0.017"/>
      </geometry>
      <origin rpy="0 0 0" xyz="0 0 0"/>
    </collision>
    <inertial>
      <mass value="0.01" />
      <origin xyz="0 0 0" />
      <inertia ixx="0.1" ixy="0.0" ixz="0.0"
                iyy="0.1" iyz="0.0"
                izz="0.1" />
    </inertial>
    <visual>
      <material
        name="">
        <color
          rgba="1.0 1.0 1.0 1" />
      </material>    
      <geometry>
        <cylinder length="0.0176" radius="0.017"/>
      </geometry>
      <origin xyz="0 0 0" rpy="0 0 0"/>
    </visual>
  </link>

  <joint name="caster_back_joint" type="fixed">
    <parent link="base_link2"/>
    <child link="caster_back_link"/>
    <origin xyz="0.0 -0.15 -0.05" rpy="${-M_PI/2} 0 ${M_PI/2}"/>
  </joint>
  <link name="caster_back_link">
    <collision>
      <geometry>
        <cylinder length="0.0176" radius="0.017"/>
      </geometry>
      <origin rpy="0 0 0" xyz="0 0 0"/>
    </collision>
    <inertial>
      <mass value="0.01" />
      <origin xyz="0 0 0" />
      <inertia ixx="0.1" ixy="0.0" ixz="0.0"
                iyy="0.1" iyz="0.0"
                izz="0.1" />
    </inertial>
    <visual>
      <material
        name="">
        <color
          rgba="1.0 1.0 1.0 1" />
      </material>    
      <geometry>
        <cylinder length="0.0176" radius="0.017"/>
      </geometry>
      <origin xyz="0 0 0" rpy="0 0 0"/>
    </visual>
  </link>

</robot>


